2017-12-24 20:53:22,082 - UserServiceImpl - 7400 - ERROR - getUserInfo - Traceback (most recent call last):
  File "C:\python27\lib\site-packages\src-0.0.1-py2.7.egg\src\main\master\service\impl\UserServiceImpl.py", line 36, in getUserInfo
    return self.userDaoInterface.getUserInfo(args)
  File "C:\python27\lib\site-packages\src-0.0.1-py2.7.egg\src\main\master\dao\UserDao.py", line 14, in getUserInfo
    daoOperate =DaoOperate(self.__name__,args)
AttributeError: UserDaoInterface instance has no attribute '__name__'

2018-04-09 14:36:34,760 - UserServiceImpl - 5640 - ERROR - addUser - {u'userName': u'test_user1', u'remarks': u'', u'userPasswd': u'123456'}
2018-04-09 14:36:34,762 - UserServiceImpl - 5640 - ERROR - addUser - <type 'dict'>
2018-04-09 14:53:48,859 - UserServiceImpl - 5640 - ERROR - addUser - {u'userName': u'testtesttest', 'remarks': None, u'userPasswd': u'12345'}
2018-04-09 14:53:48,859 - UserServiceImpl - 5640 - ERROR - addUser - <type 'dict'>
2018-04-09 14:54:58,456 - UserServiceImpl - 15816 - ERROR - addUser - {u'userName': u'test_user3', 'remarks': None, u'userPasswd': u'123456'}
2018-04-09 14:54:58,457 - UserServiceImpl - 15816 - ERROR - addUser - <type 'dict'>
2018-04-09 15:00:35,835 - UserServiceImpl - 5640 - ERROR - addUser - {u'userName': u'test_user4', 'remarks': None, u'userPasswd': u'123456'}
2018-04-09 15:00:35,835 - UserServiceImpl - 5640 - ERROR - addUser - <type 'dict'>
2018-04-09 15:03:10,882 - UserServiceImpl - 14968 - ERROR - addUser - {u'userName': u'testuseruser', 'remarks': None, u'userPasswd': u'123456'}
2018-04-09 15:03:10,882 - UserServiceImpl - 14968 - ERROR - addUser - <type 'dict'>
2018-04-09 15:29:19,161 - UserServiceImpl - 15816 - ERROR - addUser - {u'userName': u'1234567', 'remarks': None, u'userPasswd': u'1234567'}
2018-04-09 15:29:19,163 - UserServiceImpl - 15816 - ERROR - addUser - <type 'dict'>
